Workbook
Name Slicer_Discount_category: #N/A
Name Slicer_Price_Category: #N/A
Name Slicer_Rating_Category: #N/A

Sheet Excel_jumia_dataset
A1: Product | B1: Current price | C1: old price | D1: Discount | E1: Review | F1: Ratingd
A2: 115 Piece Set Of Multifunctional Precision Screwdrivers | B2: KSh 950 | C2: KSh 1,525 | D2: 0.38 | E2: -2 | F2: 4.5 out of 5
A3: Metal Decorative Hooks Key Hangers Entryway Wall Hooks Towel Hooks - Home | B3: KSh 527 | C3: KSh 999 | D3: 0.47 | E3: -14 | F3: 4.1 out of 5
A4: Portable Mini Cordless Car Vacuum Cleaner - Blue | B4: KSh 2,199 | C4: KSh 2,923 | D4: 0.25 | E4: -24 | F4: 4.6 out of 5
A5: Weighing Scale Digital Bathroom Body Fat Scale USB-Black | B5: KSh 1,580 | C5: KSh 2,499 | D5: 0.37 | E5: -7 | F5: 4.7 out of 5
A6: Portable Home Small Air Humidifier 3-Speed Fan - Green | B6: KSh 1,740 | C6: KSh 2,356 | D6: 0.26 | E6: -5 | F6: 4.8 out of 5
A7: 220V 60W Electric Soldering Iron Kits With Tools, Tips, And Multimeter | B7: KSh 2,999 | C7: KSh 3,290 | D7: 0.09 | E7: -15 | F7: 4 out of 5
A8: 137 Pieces Cake Decorating Tool Set Baking Supplies | B8: KSh 2,319 | C8: KSh 3,032 | D8: 0.24 | E8: -55 | F8: 4.6 out of 5
A9: Desk Foldable Fan Adjustable Fan Strong Wind 3 Gear Usb | B9: KSh 988 | C9: KSh 1,580 | D9: 0.37 | E9: -2 | F9: 4 out of 5
A10: LASA FOLDING TABLE SERVING STAND | B10: KSh 1,274 | C10: KSh 2,800 | D10: 0.55 | E10: -5 | F10: 4.8 out of 5
A11: 13 In 1 Home Repair Tools Box Kit Set | B11: KSh 1,600 | C11: KSh 2,929 | D11: 0.45 | E11: -5 | F11: 3.8 out of 5
A12: Genebre 115 In 1 Screwdriver Repairing Tool Set For IPhone Cellphone Hand Tool | B12: KSh 799 | C12: KSh 999 | D12: 0.2 | E12: -12 | F12: 4.1 out of 5
A13: 100 Pcs Crochet Hook Tool Set Knitting Hook Set With Box | B13: KSh 990 | C13: KSh 1,500 | D13: 0.34 | E13: -39 | F13: 4.7 out of 5
... A22: 3PCS Single Head Knitting Crochet Sweater Needle Set | B22: KSh 38 | C22: KSh 80 | D22: 0.53 | E22: -13 | F22: 3.3 out of 5
A23: 4pcs Bathroom/Kitchen Towel Rack,Roll Paper Holder,Towel Bars,Hook | B23: KSh 1,860 | C23: KSh 3,220 | D23: 0.42
A24: LED Romantic Spaceship Starry Sky Projector,Children's Bedroom Night Light-Blue | B24: KSh 880 | C24: KSh 1,350 | D24: 0.35 | E24: -6 | F24: 4 out of 5
A25: Foldable Overbed Table/Desk | B25: KSh 1,650 | C25: KSh 2,150 | D25: 0.23 | E25: -14 | F25: 4.4 out of 5
A26: LASA 3 Tier Bamboo Shoe Bench Storage Shelf | B26: KSh 2,048 | C26: KSh 4,500 | D26: 0.54 | E26: -7 | F26: 4.3 out of 5
A27: Electronic Digital Display Vernier Caliper | B27: KSh 420 | C27: KSh 647 | D27: 0.35 | E27: -49 | F27: 4.6 out of 5
A28: Portable Wardrobe Nonwoven With 3 Hanging Rods And 6 Storage Shelves | B28: KSh 2,880 | C28: KSh 3,520 | D28: 0.18 | E28: -12 | F28: 3.8 out of 5
A29: 12 Litre Black Insulated Lunch Box | B29: KSh 1,350 | C29: KSh 1,990 | D29: 0.32 | E29: -13 | F29: 3.8 out of 5
A30: 52 Pieces Cake Decorating Tool Set Gift Kit Baking Supplies | B30: KSh 1,758 | C30: KSh 2,499 | D30: 0.3 | E30: -20 | F30: 4.1 out of 5
A31: MultiFunctional Storage Rack Multi-layer Bookshelf | B31: KSh 2,200 | C31: KSh 4,080 | D31: 0.46
A32: Exfoliate And Exfoliate Face Towel - Black | B32: KSh 185 | C32: KSh 382 | D32: 0.52 | E32: -9 | F32: 4.3 out of 5
A33: 12 Litre Insulated Lunch Box Grey | B33: KSh 980 | C33: KSh 1,490 | D33: 0.34 | E33: -12 | F33: 4.7 out of 5
A34: LED Eye Protection Desk Lamp , Study, Reading, USB Fan - Double Pen Holder | B34: KSh 1,820 | C34: KSh 3,490 | D34: 0.48 | E34: -9 | F34: 4.3 out of 5
A35: 53Pcs/Set Yarn Knitting Crochet Hooks With Bag - Fortune Cat | B35: KSh 1,940 | C35: KSh 2,650 | D35: 0.27 | E35: -20 | F35: 4.7 out of 5
A36: 53 Pieces/Set Yarn Knitting Crochet Hooks With Bag - Pansies | B36: KSh 1,980 | C36: KSh 2,699 | D36: 0.27 | E36: -32 | F36: 4.5 out of 5
A37: DIY File Folder, Office Drawer File Holder, Pen Holder, Desktop Storage Rack | B37: KSh 1,620 | C37: KSh 2,690 | D37: 0.4 | E37: -1 | F37: 5 out of 5
A38: Classic Black Cat Cotton Hemp Pillow Case For Home Car | B38: KSh 171 | C38: KSh 360 | D38: 0.53 | E38: -2 | F38: 5 out of 5
A39: Punch-free Great Load Bearing Bathroom Storage Rack Wall Shelf-White | B39: KSh 389 | C39: KSh 656 | D39: 0.41 | E39: -36 | F39: 4.3 out of 5
A40: 1/2/3 Seater Elastic Sofa Cover,Living Room/Home Decor Chair Cover-Grey | B40: KSh 1,620 - KSh 1,980 | C40: KSh 2,200 - KSh 3,200 | D40: 0.38 | E40: -2 | F40: 4.5 out of 5
A41: LASA Stainless Steel Double Wall Mount Soap Dispenser - 500ml | B41: KSh 2,750 | C41: KSh 4,471 | D41: 0.38
A42: 4M Float Switch Water Level Controller -Water Tank | B42: KSh 475 | C42: KSh 931 | D42: 0.49
A43: Modern Sofa Throw Pillow Cover-45x45cm-Blue&Red | B43: KSh 238 | C43: KSh 476 | D43: 0.5
A44: Balloon Insert, Birthday Party Balloon Set, PU Leather | B44: KSh 610 | C44: KSh 1,060 | D44: 0.42
A45: Balloon Insert, Birthday Party Balloon Set, PU Leather | B45: KSh 610 | C45: KSh 1,060 | D45: 0.42
A46: Shower Cap Wide Elastic Band Cover Reusable Bashroom Cap | B46: KSh 2,132 | C46: KSh 2,169 | D46: 0.02
A47: Christmas Elk Fence Yard Lawn Decorations Cute For Holidays | B47: KSh 999 | C47: KSh 2,000 | D47: 0.5
A48: 60W Hot Melt Glue Sprayer - Efficient And Stable Glue Dispensing | B48: KSh 1,190 | C48: KSh 1,785 | D48: 0.33
...

Sheet CLEANED
A1: Product | B1: Current price | C1: Old price | D1: Discount Price | E1: Discount | F1: Discount category | G1: Review | H1: Ratingd | I1: Rating Category | J1: Price Category
A2: 115 Piece Set Of Multifunctional Precision Screwdrivers | B2: 950 | C2: 1525 | D2: =C2-B2 -> 575 | E2: 0.38 | F2: =IF(E2<20%,"LOW DISCOUNT",IF(E2<40%,"MEDIUM DISCOUNT","HIGH DISCOUNT")) -> MEDIUM DISCOUNT | G2: 2 | H2: 4.5 | I2: =IF(ISBLANK(H2),"NOT PROVIDED",IF(H2<3,"POOR",IF(H2<4.5,"AVERAGE","EXCELLENT"))) -> EXCELLENT | J2: =IF(B2<1000,"LOW PRICE",IF(B2<2000,"MEDIUM PRICE","HIGH PRICE")) -> LOW PRICE
A3: Metal Decorative Hooks Key Hangers Entryway Wall Hooks Towel Hooks - Home | B3: 527 | C3: 999 | D3: =C3-B3 -> 472 | E3: 0.47 | F3: =IF(E3<20%,"LOW DISCOUNT",IF(E3<40%,"MEDIUM DISCOUNT","HIGH DISCOUNT")) -> HIGH DISCOUNT | G3: 14 | H3: 4.1 | I3: =IF(ISBLANK(H3),"NOT PROVIDED",IF(H3<3,"POOR",IF(H3<4.5,"AVERAGE","EXCELLENT"))) -> AVERAGE | J3: =IF(B3<1000,"LOW PRICE",IF(B3<2000,"MEDIUM PRICE","HIGH PRICE")) -> LOW PRICE
A4: Portable Mini Cordless Car Vacuum Cleaner - Blue | B4: 2199 | C4: 2923 | D4: =C4-B4 -> 724 | E4: 0.25 | F4: =IF(E4<20%,"LOW DISCOUNT",IF(E4<40%,"MEDIUM DISCOUNT","HIGH DISCOUNT")) -> MEDIUM DISCOUNT | G4: 24 | H4: 4.6 | I4: =IF(ISBLANK(H4),"NOT PROVIDED",IF(H4<3,"POOR",IF(H4<4.5,"AVERAGE","EXCELLENT"))) -> EXCELLENT | J4: =IF(B4<1000,"LOW PRICE",IF(B4<2000,"MEDIUM PRICE","HIGH PRICE")) -> HIGH PRICE
A5: Weighing Scale Digital Bathroom Body Fat Scale USB-Black | B5: 1580 | C5: 2499 | D5: =C5-B5 -> 919 | E5: 0.37 | F5: =IF(E5<20%,"LOW DISCOUNT",IF(E5<40%,"MEDIUM DISCOUNT","HIGH DISCOUNT")) -> MEDIUM DISCOUNT | G5: 7 | H5: 4.7 | I5: =IF(ISBLANK(H5),"NOT PROVIDED",IF(H5<3,"POOR",IF(H5<4.5,"AVERAGE","EXCELLENT"))) -> EXCELLENT | J5: =IF(B5<1000,"LOW PRICE",IF(B5<2000,"MEDIUM PRICE","HIGH PRICE")) -> MEDIUM PRICE
A6: Portable Home Small Air Humidifier 3-Speed Fan - Green | B6: 1740 | C6: 2356 | D6: =C6-B6 -> 616 | E6: 0.26 | F6: =IF(E6<20%,"LOW DISCOUNT",IF(E6<40%,"MEDIUM DISCOUNT","HIGH DISCOUNT")) -> MEDIUM DISCOUNT | G6: 5 | H6: 4.8 | I6: =IF(ISBLANK(H6),"NOT PROVIDED",IF(H6<3,"POOR",IF(H6<4.5,"AVERAGE","EXCELLENT"))) -> EXCELLENT | J6: =IF(B6<1000,"LOW PRICE",IF(B6<2000,"MEDIUM PRICE","HIGH PRICE")) -> MEDIUM PRICE
A7: 220V 60W Electric Soldering Iron Kits With Tools, Tips, And Multimeter | B7: 2999 | C7: 3290 | D7: =C7-B7 -> 291 | E7: 0.09 | F7: =IF(E7<20%,"LOW DISCOUNT",IF(E7<40%,"MEDIUM DISCOUNT","HIGH DISCOUNT")) -> LOW DISCOUNT | G7: 15 | H7: 4 | I7: =IF(ISBLANK(H7),"NOT PROVIDED",IF(H7<3,"POOR",IF(H7<4.5,"AVERAGE","EXCELLENT"))) -> AVERAGE | J7: =IF(B7<1000,"LOW PRICE",IF(B7<2000,"MEDIUM PRICE","HIGH PRICE")) -> HIGH PRICE
A8: 137 Pieces Cake Decorating Tool Set Baking Supplies | B8: 2319 | C8: 3032 | D8: =C8-B8 -> 713 | E8: 0.24 | F8: =IF(E8<20%,"LOW DISCOUNT",IF(E8<40%,"MEDIUM DISCOUNT","HIGH DISCOUNT")) -> MEDIUM DISCOUNT | G8: 55 | H8: 4.6 | I8: =IF(ISBLANK(H8),"NOT PROVIDED",IF(H8<3,"POOR",IF(H8<4.5,"AVERAGE","EXCELLENT"))) -> EXCELLENT | J8: =IF(B8<1000,"LOW PRICE",IF(B8<2000,"MEDIUM PRICE","HIGH PRICE")) -> HIGH PRICE
A9: Desk Foldable Fan Adjustable Fan Strong Wind 3 Gear Usb | B9: 988 | C9: 1580 | D9: =C9-B9 -> 592 | E9: 0.37 | F9: =IF(E9<20%,"LOW DISCOUNT",IF(E9<40%,"MEDIUM DISCOUNT","HIGH DISCOUNT")) -> MEDIUM DISCOUNT | G9: 2 | H9: 4 | I9: =IF(ISBLANK(H9),"NOT PROVIDED",IF(H9<3,"POOR",IF(H9<4.5,"AVERAGE","EXCELLENT"))) -> AVERAGE | J9: =IF(B9<1000,"LOW PRICE",IF(B9<2000,"MEDIUM PRICE","HIGH PRICE")) -> LOW PRICE
A10: LASA FOLDING TABLE SERVING STAND | B10: 1274 | C10: 2800 | D10: =C10-B10 -> 1526 | E10: 0.55 | F10: =IF(E10<20%,"LOW DISCOUNT",IF(E10<40%,"MEDIUM DISCOUNT","HIGH DISCOUNT")) -> HIGH DISCOUNT | G10: 5 | H10: 4.8 | I10: =IF(ISBLANK(H10),"NOT PROVIDED",IF(H10<3,"POOR",IF(H10<4.5,"AVERAGE","EXCELLENT"))) -> EXCELLENT | J10: =IF(B10<1000,"LOW PRICE",IF(B10<2000,"MEDIUM PRICE","HIGH PRICE")) -> MEDIUM PRICE
A11: 13 In 1 Home Repair Tools Box Kit Set | B11: 1600 | C11: 2929 | D11: =C11-B11 -> 1329 | E11: 0.45 | F11: =IF(E11<20%,"LOW DISCOUNT",IF(E11<40%,"MEDIUM DISCOUNT","HIGH DISCOUNT")) -> HIGH DISCOUNT | G11: 5 | H11: 3.8 | I11: =IF(ISBLANK(H11),"NOT PROVIDED",IF(H11<3,"POOR",IF(H11<4.5,"AVERAGE","EXCELLENT"))) -> AVERAGE | J11: =IF(B11<1000,"LOW PRICE",IF(B11<2000,"MEDIUM PRICE","HIGH PRICE")) -> MEDIUM PRICE
A12: Genebre 115 In 1 Screwdriver Repairing Tool Set For IPhone Cellphone Hand Tool | B12: 799 | C12: 999 | D12: =C12-B12 -> 200 | E12: 0.2 | F12: =IF(E12<20%,"LOW DISCOUNT",IF(E12<40%,"MEDIUM DISCOUNT","HIGH DISCOUNT")) -> MEDIUM DISCOUNT | G12: 12 | H12: 4.1 | I12: =IF(ISBLANK(H12),"NOT PROVIDED",IF(H12<3,"POOR",IF(H12<4.5,"AVERAGE","EXCELLENT"))) -> AVERAGE | J12: =IF(B12<1000,"LOW PRICE",IF(B12<2000,"MEDIUM PRICE","HIGH PRICE")) -> LOW PRICE
A13: 100 Pcs Crochet Hook Tool Set Knitting Hook Set With Box | B13: 990 | C13: 1500 | D13: =C13-B13 -> 510 | E13: 0.34 | F13: =IF(E13<20%,"LOW DISCOUNT",IF(E13<40%,"MEDIUM DISCOUNT","HIGH DISCOUNT")) -> MEDIUM DISCOUNT | G13: 39 | H13: 4.7 | I13: =IF(ISBLANK(H13),"NOT PROVIDED",IF(H13<3,"POOR",IF(H13<4.5,"AVERAGE","EXCELLENT"))) -> EXCELLENT | J13: =IF(B13<1000,"LOW PRICE",IF(B13<2000,"MEDIUM PRICE","HIGH PRICE")) -> LOW PRICE
... A22: 3PCS Single Head Knitting Crochet Sweater Needle Set | B22: 38 | C22: 80 | D22: =C22-B22 -> 42 | E22: 0.53 | F22: =IF(E22<20%,"LOW DISCOUNT",IF(E22<40%,"MEDIUM DISCOUNT","HIGH DISCOUNT")) -> HIGH DISCOUNT | G22: 13 | H22: 3.3 | I22: =IF(ISBLANK(H22),"NOT PROVIDED",IF(H22<3,"POOR",IF(H22<4.5,"AVERAGE","EXCELLENT"))) -> AVERAGE | J22: =IF(B22<1000,"LOW PRICE",IF(B22<2000,"MEDIUM PRICE","HIGH PRICE")) -> LOW PRICE
A23: 4pcs Bathroom/Kitchen Towel Rack,Roll Paper Holder,Towel Bars,Hook | B23: 1860 | C23: 3220 | D23: =C23-B23 -> 1360 | E23: 0.42 | F23: =IF(E23<20%,"LOW DISCOUNT",IF(E23<40%,"MEDIUM DISCOUNT","HIGH DISCOUNT")) -> HIGH DISCOUNT | I23: =IF(ISBLANK(H23),"NOT PROVIDED",IF(H23<3,"POOR",IF(H23<4.5,"AVERAGE","EXCELLENT"))) -> NOT PROVIDED | J23: =IF(B23<1000,"LOW PRICE",IF(B23<2000,"MEDIUM PRICE","HIGH PRICE")) -> MEDIUM PRICE
A24: LED Romantic Spaceship Starry Sky Projector,Children's Bedroom Night Light-Blue | B24: 880 | C24: 1350 | D24: =C24-B24 -> 470 | E24: 0.35 | F24: =IF(E24<20%,"LOW DISCOUNT",IF(E24<40%,"MEDIUM DISCOUNT","HIGH DISCOUNT")) -> MEDIUM DISCOUNT | G24: 6 | H24: 4 | I24: =IF(ISBLANK(H24),"NOT PROVIDED",IF(H24<3,"POOR",IF(H24<4.5,"AVERAGE","EXCELLENT"))) -> AVERAGE | J24: =IF(B24<1000,"LOW PRICE",IF(B24<2000,"MEDIUM PRICE","HIGH PRICE")) -> LOW PRICE
A25: Foldable Overbed Table/Desk | B25: 1650 | C25: 2150 | D25: =C25-B25 -> 500 | E25: 0.23 | F25: =IF(E25<20%,"LOW DISCOUNT",IF(E25<40%,"MEDIUM DISCOUNT","HIGH DISCOUNT")) -> MEDIUM DISCOUNT | G25: 14 | H25: 4.4 | I25: =IF(ISBLANK(H25),"NOT PROVIDED",IF(H25<3,"POOR",IF(H25<4.5,"AVERAGE","EXCELLENT"))) -> AVERAGE | J25: =IF(B25<1000,"LOW PRICE",IF(B25<2000,"MEDIUM PRICE","HIGH PRICE")) -> MEDIUM PRICE
A26: LASA 3 Tier Bamboo Shoe Bench Storage Shelf | B26: 2048 | C26: 4500 | D26: =C26-B26 -> 2452 | E26: 0.54 | F26: =IF(E26<20%,"LOW DISCOUNT",IF(E26<40%,"MEDIUM DISCOUNT","HIGH DISCOUNT")) -> HIGH DISCOUNT | G26: 7 | H26: 4.3 | I26: =IF(ISBLANK(H26),"NOT PROVIDED",IF(H26<3,"POOR",IF(H26<4.5,"AVERAGE","EXCELLENT"))) -> AVERAGE | J26: =IF(B26<1000,"LOW PRICE",IF(B26<2000,"MEDIUM PRICE","HIGH PRICE")) -> HIGH PRICE
A27: Electronic Digital Display Vernier Caliper | B27: 420 | C27: 647 | D27: =C27-B27 -> 227 | E27: 0.35 | F27: =IF(E27<20%,"LOW DISCOUNT",IF(E27<40%,"MEDIUM DISCOUNT","HIGH DISCOUNT")) -> MEDIUM DISCOUNT | G27: 49 | H27: 4.6 | I27: =IF(ISBLANK(H27),"NOT PROVIDED",IF(H27<3,"POOR",IF(H27<4.5,"AVERAGE","EXCELLENT"))) -> EXCELLENT | J27: =IF(B27<1000,"LOW PRICE",IF(B27<2000,"MEDIUM PRICE","HIGH PRICE")) -> LOW PRICE
A28: Portable Wardrobe Nonwoven With 3 Hanging Rods And 6 Storage Shelves | B28: 2880 | C28: 3520 | D28: =C28-B28 -> 640 | E28: 0.18 | F28: =IF(E28<20%,"LOW DISCOUNT",IF(E28<40%,"MEDIUM DISCOUNT","HIGH DISCOUNT")) -> LOW DISCOUNT | G28: 12 | H28: 3.8 | I28: =IF(ISBLANK(H28),"NOT PROVIDED",IF(H28<3,"POOR",IF(H28<4.5,"AVERAGE","EXCELLENT"))) -> AVERAGE | J28: =IF(B28<1000,"LOW PRICE",IF(B28<2000,"MEDIUM PRICE","HIGH PRICE")) -> HIGH PRICE
A29: 12 Litre Black Insulated Lunch Box | B29: 1350 | C29: 1990 | D29: =C29-B29 -> 640 | E29: 0.32 | F29: =IF(E29<20%,"LOW DISCOUNT",IF(E29<40%,"MEDIUM DISCOUNT","HIGH DISCOUNT")) -> MEDIUM DISCOUNT | G29: 13 | H29: 3.8 | I29: =IF(ISBLANK(H29),"NOT PROVIDED",IF(H29<3,"POOR",IF(H29<4.5,"AVERAGE","EXCELLENT"))) -> AVERAGE | J29: =IF(B29<1000,"LOW PRICE",IF(B29<2000,"MEDIUM PRICE","HIGH PRICE")) -> MEDIUM PRICE
A30: 52 Pieces Cake Decorating Tool Set Gift Kit Baking Supplies | B30: 1758 | C30: 2499 | D30: =C30-B30 -> 741 | E30: 0.3 | F30: =IF(E30<20%,"LOW DISCOUNT",IF(E30<40%,"MEDIUM DISCOUNT","HIGH DISCOUNT")) -> MEDIUM DISCOUNT | G30: 20 | H30: 4.1 | I30: =IF(ISBLANK(H30),"NOT PROVIDED",IF(H30<3,"POOR",IF(H30<4.5,"AVERAGE","EXCELLENT"))) -> AVERAGE | J30: =IF(B30<1000,"LOW PRICE",IF(B30<2000,"MEDIUM PRICE","HIGH PRICE")) -> MEDIUM PRICE
A31: MultiFunctional Storage Rack Multi-layer Bookshelf | B31: 2200 | C31: 4080 | D31: =C31-B31 -> 1880 | E31: 0.46 | F31: =IF(E31<20%,"LOW DISCOUNT",IF(E31<40%,"MEDIUM DISCOUNT","HIGH DISCOUNT")) -> HIGH DISCOUNT | I31: =IF(ISBLANK(H31),"NOT PROVIDED",IF(H31<3,"POOR",IF(H31<4.5,"AVERAGE","EXCELLENT"))) -> NOT PROVIDED | J31: =IF(B31<1000,"LOW PRICE",IF(B31<2000,"MEDIUM PRICE","HIGH PRICE")) -> HIGH PRICE
A32: Exfoliate And Exfoliate Face Towel - Black | B32: 185 | C32: 382 | D32: =C32-B32 -> 197 | E32: 0.52 | F32: =IF(E32<20%,"LOW DISCOUNT",IF(E32<40%,"MEDIUM DISCOUNT","HIGH DISCOUNT")) -> HIGH DISCOUNT | G32: 9 | H32: 4.3 | I32: =IF(ISBLANK(H32),"NOT PROVIDED",IF(H32<3,"POOR",IF(H32<4.5,"AVERAGE","EXCELLENT"))) -> AVERAGE | J32: =IF(B32<1000,"LOW PRICE",IF(B32<2000,"MEDIUM PRICE","HIGH PRICE")) -> LOW PRICE
A33: 12 Litre Insulated Lunch Box Grey | B33: 980 | C33: 1490 | D33: =C33-B33 -> 510 | E33: 0.34 | F33: =IF(E33<20%,"LOW DISCOUNT",IF(E33<40%,"MEDIUM DISCOUNT","HIGH DISCOUNT")) -> MEDIUM DISCOUNT | G33: 12 | H33: 4.7 | I33: =IF(ISBLANK(H33),"NOT PROVIDED",IF(H33<3,"POOR",IF(H33<4.5,"AVERAGE","EXCELLENT"))) -> EXCELLENT | J33: =IF(B33<1000,"LOW PRICE",IF(B33<2000,"MEDIUM PRICE","HIGH PRICE")) -> LOW PRICE
A34: LED Eye Protection Desk Lamp , Study, Reading, USB Fan - Double Pen Holder | B34: 1820 | C34: 3490 | D34: =C34-B34 -> 1670 | E34: 0.48 | F34: =IF(E34<20%,"LOW DISCOUNT",IF(E34<40%,"MEDIUM DISCOUNT","HIGH DISCOUNT")) -> HIGH DISCOUNT | G34: 9 | H34: 4.3 | I34: =IF(ISBLANK(H34),"NOT PROVIDED",IF(H34<3,"POOR",IF(H34<4.5,"AVERAGE","EXCELLENT"))) -> AVERAGE | J34: =IF(B34<1000,"LOW PRICE",IF(B34<2000,"MEDIUM PRICE","HIGH PRICE")) -> MEDIUM PRICE
A35: 53Pcs/Set Yarn Knitting Crochet Hooks With Bag - Fortune Cat | B35: 1940 | C35: 2650 | D35: =C35-B35 -> 710 | E35: 0.27 | F35: =IF(E35<20%,"LOW DISCOUNT",IF(E35<40%,"MEDIUM DISCOUNT","HIGH DISCOUNT")) -> MEDIUM DISCOUNT | G35: 20 | H35: 4.7 | I35: =IF(ISBLANK(H35),"NOT PROVIDED",IF(H35<3,"POOR",IF(H35<4.5,"AVERAGE","EXCELLENT"))) -> EXCELLENT | J35: =IF(B35<1000,"LOW PRICE",IF(B35<2000,"MEDIUM PRICE","HIGH PRICE")) -> MEDIUM PRICE
A36: 53 Pieces/Set Yarn Knitting Crochet Hooks With Bag - Pansies | B36: 1980 | C36: 2699 | D36: =C36-B36 -> 719 | E36: 0.27 | F36: =IF(E36<20%,"LOW DISCOUNT",IF(E36<40%,"MEDIUM DISCOUNT","HIGH DISCOUNT")) -> MEDIUM DISCOUNT | G36: 32 | H36: 4.5 | I36: =IF(ISBLANK(H36),"NOT PROVIDED",IF(H36<3,"POOR",IF(H36<4.5,"AVERAGE","EXCELLENT"))) -> EXCELLENT | J36: =IF(B36<1000,"LOW PRICE",IF(B36<2000,"MEDIUM PRICE","HIGH PRICE")) -> MEDIUM PRICE
A37: DIY File Folder, Office Drawer File Holder, Pen Holder, Desktop Storage Rack | B37: 1620 | C37: 2690 | D37: =C37-B37 -> 1070 | E37: 0.4 | F37: =IF(E37<20%,"LOW DISCOUNT",IF(E37<40%,"MEDIUM DISCOUNT","HIGH DISCOUNT")) -> HIGH DISCOUNT | G37: 1 | H37: 5 | I37: =IF(ISBLANK(H37),"NOT PROVIDED",IF(H37<3,"POOR",IF(H37<4.5,"AVERAGE","EXCELLENT"))) -> EXCELLENT | J37: =IF(B37<1000,"LOW PRICE",IF(B37<2000,"MEDIUM PRICE","HIGH PRICE")) -> MEDIUM PRICE
A38: Classic Black Cat Cotton Hemp Pillow Case For Home Car | B38: 171 | C38: 360 | D38: =C38-B38 -> 189 | E38: 0.53 | F38: =IF(E38<20%,"LOW DISCOUNT",IF(E38<40%,"MEDIUM DISCOUNT","HIGH DISCOUNT")) -> HIGH DISCOUNT | G38: 2 | H38: 5 | I38: =IF(ISBLANK(H38),"NOT PROVIDED",IF(H38<3,"POOR",IF(H38<4.5,"AVERAGE","EXCELLENT"))) -> EXCELLENT | J38: =IF(B38<1000,"LOW PRICE",IF(B38<2000,"MEDIUM PRICE","HIGH PRICE")) -> LOW PRICE
A39: Punch-free Great Load Bearing Bathroom Storage Rack Wall Shelf-White | B39: 389 | C39: 656 | D39: =C39-B39 -> 267 | E39: 0.41 | F39: =IF(E39<20%,"LOW DISCOUNT",IF(E39<40%,"MEDIUM DISCOUNT","HIGH DISCOUNT")) -> HIGH DISCOUNT | G39: 36 | H39: 4.3 | I39: =IF(ISBLANK(H39),"NOT PROVIDED",IF(H39<3,"POOR",IF(H39<4.5,"AVERAGE","EXCELLENT"))) -> AVERAGE | J39: =IF(B39<1000,"LOW PRICE",IF(B39<2000,"MEDIUM PRICE","HIGH PRICE")) -> LOW PRICE
A40: 1/2/3 Seater Elastic Sofa Cover,Living Room | B40: 1620 | C40: 2200 | D40: =C40-B40 -> 580 | E40: 0.26 | F40: =IF(E40<20%,"LOW DISCOUNT",IF(E40<40%,"MEDIUM DISCOUNT","HIGH DISCOUNT")) -> MEDIUM DISCOUNT | G40: 2 | H40: 4.5 | I40: =IF(ISBLANK(H40),"NOT PROVIDED",IF(H40<3,"POOR",IF(H40<4.5,"AVERAGE","EXCELLENT"))) -> EXCELLENT | J40: =IF(B40<1000,"LOW PRICE",IF(B40<2000,"MEDIUM PRICE","HIGH PRICE")) -> MEDIUM PRICE
A41: Home Decor Chair Cover-Grey | B41: 1980 | C41: 3200 | D41: =C41-B41 -> 1220 | E41: 0.38 | F41: =IF(E41<20%,"LOW DISCOUNT",IF(E41<40%,"MEDIUM DISCOUNT","HIGH DISCOUNT")) -> MEDIUM DISCOUNT | I41: =IF(ISBLANK(H41),"NOT PROVIDED",IF(H41<3,"POOR",IF(H41<4.5,"AVERAGE","EXCELLENT"))) -> NOT PROVIDED | J41: =IF(B41<1000,"LOW PRICE",IF(B41<2000,"MEDIUM PRICE","HIGH PRICE")) -> MEDIUM PRICE
A42: LASA Stainless Steel Double Wall Mount Soap Dispenser - 500ml | B42: 2750 | C42: 4471 | D42: =C42-B42 -> 1721 | E42: 0.38 | F42: =IF(E42<20%,"LOW DISCOUNT",IF(E42<40%,"MEDIUM DISCOUNT","HIGH DISCOUNT")) -> MEDIUM DISCOUNT | I42: =IF(ISBLANK(H42),"NOT PROVIDED",IF(H42<3,"POOR",IF(H42<4.5,"AVERAGE","EXCELLENT"))) -> NOT PROVIDED | J42: =IF(B42<1000,"LOW PRICE",IF(B42<2000,"MEDIUM PRICE","HIGH PRICE")) -> HIGH PRICE
A43: 4M Float Switch Water Level Controller -Water Tank | B43: 475 | C43: 931 | D43: =C43-B43 -> 456 | E43: 0.49 | F43: =IF(E43<20%,"LOW DISCOUNT",IF(E43<40%,"MEDIUM DISCOUNT","HIGH DISCOUNT")) -> HIGH DISCOUNT | I43: =IF(ISBLANK(H43),"NOT PROVIDED",IF(H43<3,"POOR",IF(H43<4.5,"AVERAGE","EXCELLENT"))) -> NOT PROVIDED | J43: =IF(B43<1000,"LOW PRICE",IF(B43<2000,"MEDIUM PRICE","HIGH PRICE")) -> LOW PRICE
A44: Modern Sofa Throw Pillow Cover-45x45cm-Blue&Red | B44: 238 | C44: 476 | D44: =C44-B44 -> 238 | E44: 0.5 | F44: =IF(E44<20%,"LOW DISCOUNT",IF(E44<40%,"MEDIUM DISCOUNT","HIGH DISCOUNT")) -> HIGH DISCOUNT | I44: =IF(ISBLANK(H44),"NOT PROVIDED",IF(H44<3,"POOR",IF(H44<4.5,"AVERAGE","EXCELLENT"))) -> NOT PROVIDED | J44: =IF(B44<1000,"LOW PRICE",IF(B44<2000,"MEDIUM PRICE","HIGH PRICE")) -> LOW PRICE
A45: Balloon Insert, Birthday Party Balloon Set, PU Leather | B45: 610 | C45: 1060 | D45: =C45-B45 -> 450 | E45: 0.42 | F45: =IF(E45<20%,"LOW DISCOUNT",IF(E45<40%,"MEDIUM DISCOUNT","HIGH DISCOUNT")) -> HIGH DISCOUNT | I45: =IF(ISBLANK(H45),"NOT PROVIDED",IF(H45<3,"POOR",IF(H45<4.5,"AVERAGE","EXCELLENT"))) -> NOT PROVIDED | J45: =IF(B45<1000,"LOW PRICE",IF(B45<2000,"MEDIUM PRICE","HIGH PRICE")) -> LOW PRICE
A46: Shower Cap Wide Elastic Band Cover Reusable Bashroom Cap | B46: 2132 | C46: 2169 | D46: =C46-B46 -> 37 | E46: 0.02 | F46: =IF(E46<20%,"LOW DISCOUNT",IF(E46<40%,"MEDIUM DISCOUNT","HIGH DISCOUNT")) -> LOW DISCOUNT | I46: =IF(ISBLANK(H46),"NOT PROVIDED",IF(H46<3,"POOR",IF(H46<4.5,"AVERAGE","EXCELLENT"))) -> NOT PROVIDED | J46: =IF(B46<1000,"LOW PRICE",IF(B46<2000,"MEDIUM PRICE","HIGH PRICE")) -> HIGH PRICE
A47: Christmas Elk Fence Yard Lawn Decorations Cute For Holidays | B47: 999 | C47: 2000 | D47: =C47-B47 -> 1001 | E47: 0.5 | F47: =IF(E47<20%,"LOW DISCOUNT",IF(E47<40%,"MEDIUM DISCOUNT","HIGH DISCOUNT")) -> HIGH DISCOUNT | I47: =IF(ISBLANK(H47),"NOT PROVIDED",IF(H47<3,"POOR",IF(H47<4.5,"AVERAGE","EXCELLENT"))) -> NOT PROVIDED | J47: =IF(B47<1000,"LOW PRICE",IF(B47<2000,"MEDIUM PRICE","HIGH PRICE")) -> LOW PRICE
A48: 60W Hot Melt Glue Sprayer - Efficient And Stable Glue Dispensing | B48: 1190 | C48: 1785 | D48: =C48-B48 -> 595 | E48: 0.33 | F48: =IF(E48<20%,"LOW DISCOUNT",IF(E48<40%,"MEDIUM DISCOUNT","HIGH DISCOUNT")) -> MEDIUM DISCOUNT | I48: =IF(ISBLANK(H48),"NOT PROVIDED",IF(H48<3,"POOR",IF(H48<4.5,"AVERAGE","EXCELLENT"))) -> NOT PROVIDED | J48: =IF(B48<1000,"LOW PRICE",IF(B48<2000,"MEDIUM PRICE","HIGH PRICE")) -> MEDIUM PRICE
...

Sheet Sheet11
A3: Average of Discount Price
A4: 626.65487

Sheet DESCRIPTIVE STATISTICS
A1: Descriptive statistics
A2: Average current price of products | B2: =AVERAGE(CLEANED!B1:B114) -> 1192.3186
A3: Average old price of products | B3: =AVERAGE(CLEANED!C1:C114) -> 1818.9735
A4: Average discount percentage | B4: {=AVERAGE(CLEANED!E1:E114)} -> 0.36681416
A5: Average product rating | B5: =AVERAGE(CLEANED!H1:H24) -> 4.4409091
A6: Total number of products | B6: =COUNTA(CLEANED!A1:A114) -> 114
A7: Total number of reviews | B7: =SUM(CLEANED!G1:G22) -> 281
A8: Most expensive product | B8: =_xlfn.XLOOKUP(MAX(CLEANED!B2:B114),CLEANED!B2:B114,CLEANED!A2:A114) -> 32PCS Portable Cordless Drill Set With Cyclic Battery Drive -26 Variable Speed
A9: Least expensive product | B9: =_xlfn.XLOOKUP(MIN(CLEANED!B2:B114),CLEANED!B2:B114,CLEANED!A2:A114) -> 3PCS Single Head Knitting Crochet Sweater Needle Set
A12: Trend Analysis
A13: Does a higher discount percentage result in more customer reviews? | B13: =CORREL(CLEANED!E2:E114,CLEANED!G2:G114) -> -0.12231526 | C13: No relatioship
A14: Do highly rated products receive more customer reviews? | B14: =CORREL(CLEANED!H2:H114,CLEANED!G2:G114) -> 0.057209035 | C14: A positive relationship
A15: Are expensive products rated higher than cheaper products? | C15: Expensive products have a higher average rating than cheaper products
A17: Identify the top 5 products with the highest rankings.
A18: Identify the top 5 products with the lowest ratings .
A20: MEDIAN | B20: =MEDIAN(CLEANED!B2:B114) -> 999
A21: Average rating for products above median(expensive product average) | B21: =AVERAGEIF(CLEANED!B2:B114,">999",CLEANED!H2:H22) -> 3.9448276
A22: average rating for products below median(Cheaper product) | B22: =AVERAGEIF(CLEANED!B2:B114,"<999",CLEANED!H2:H22) -> 3.8321429

Sheet TOP 5 LOWEST RANKING
A1: {=_xlfn._xlws.SORT(CLEANED!A2:J114,8,1)} -> Wall-mounted Sticker Punch-free Plug Fixer | B1: 450 | C1: 900 | D1: 450 | E1: 0.5 | F1: HIGH DISCOUNT | G1: 1 | H1: 2 | I1: POOR | J1: LOW PRICE
A2: 5-PCS Stainless Steel Cooking Pot Set With Steamed Slices | B2: 2115 | C2: 4700 | D2: 2585 | E2: 0.55 | F2: HIGH DISCOUNT | G2: 13 | H2: 2.1 | I2: POOR | J2: HIGH PRICE
A3: Electric LED UV Mosquito Killer Lamp, Outdoor/Indoor Fly Killer Trap Light -USB | B3: 1570 | C3: 2988 | D3: 1418 | E3: 0.47 | F3: HIGH DISCOUNT | G3: 7 | H3: 2.1 | I3: POOR | J3: MEDIUM PRICE
A4: Artificial Potted Flowers Room Decorative Flowers (2 Pieces) | B4: 990 | C4: 1814 | D4: 824 | E4: 0.45 | F4: HIGH DISCOUNT | G4: 6 | H4: 2.2 | I4: POOR | J4: LOW PRICE
A5: 7-piece Set Of Storage Bags, Travel Storage Bags, Shoe Bags | B5: 968 | C5: 1814 | D5: 846 | E5: 0.47 | F5: HIGH DISCOUNT | G5: 6 | H5: 2.2 | I5: POOR | J5: LOW PRICE
A6: 380ML USB Rechargeable Portable Small Blenders And Juicers | B6: 1000 | C6: 2000 | D6: 1000 | E6: 0.5 | F6: HIGH DISCOUNT | G6: 7 | H6: 2.3 | I6: POOR | J6: MEDIUM PRICE
A7: Watercolour Gold Foil Textured Print Pillow Cover | B7: 345 | C7: 602 | D7: 257 | E7: 0.43 | F7: HIGH DISCOUNT | G7: 6 | H7: 2.3 | I7: POOR | J7: LOW PRICE
A8: 5 Pieces/set Of Stainless Steel Induction Cooker Pots | B8: 2170 | C8: 2500 | D8: 330 | E8: 0.13 | F8: LOW DISCOUNT | G8: 6 | H8: 2.5 | I8: POOR | J8: HIGH PRICE
A9: Agapeon Toothbrush Holder And Toothpaste Dispenser | B9: 382 | C9: 700 | D9: 318 | E9: 0.45 | F9: HIGH DISCOUNT | G9: 17 | H9: 2.6 | I9: POOR | J9: LOW PRICE
A10: Intelligent LED Body Sensor Wireless Lighting Night Light USB | B10: 325 | C10: 680 | D10: 355 | E10: 0.52 | F10: HIGH DISCOUNT | G10: 15 | H10: 2.7 | I10: POOR | J10: LOW PRICE
A11: 120W Cordless Vacuum Cleaners Handheld Electric Vacuum Cleaner | B11: 445 | C11: 873 | D11: 428 | E11: 0.49 | F11: HIGH DISCOUNT | G11: 69 | H11: 2.8 | I11: POOR | J11: LOW PRICE
A12: VIC Wireless Vacuum Cleaner Dual Use For Home And Car 120W High Power Powerful | B12: 1220 | C12: 1555 | D12: 335 | E12: 0.22 | F12: MEDIUM DISCOUNT | G12: 16 | H12: 2.9 | I12: POOR | J12: MEDIUM PRICE
A13: Mythco 120COB Solar Wall Ligt With Motion Sensor And Remote Control 3 Modes | B13: 458 | C13: 986 | D13: 528 | E13: 0.54 | F13: HIGH DISCOUNT | G13: 10 | H13: 3 | I13: AVERAGE | J13: LOW PRICE
... A113: Black Simple Water Cup Wine Coaster Anti Slip Absorbent | B113: 169 | C113: 320 | D113: 151 | E113: 0.47 | F113: HIGH DISCOUNT | G113: 0 | H113: 0 | I113: NOT PROVIDED | J113: LOW PRICE

Sheet TOP 10 RATING BY DISCOUNT 
A1: Product | B1: Current price | C1: Old price | D1: Discount Price | E1: Discount | F1: Discount category | G1: Review | H1: Ratingd | I1: Rating Category | J1: Price Category
A2: Anti-Skid Absorbent Insulation Coaster For Home Office | B2: 332 | C2: 684 | D2: =C2-B2 -> 352 | E2: 0.51 | F2: =IF(E2<20%,"LOW DISCOUNT",IF(E2<40%,"MEDIUM DISCOUNT","HIGH DISCOUNT")) -> HIGH DISCOUNT | G2: 2 | H2: 5 | I2: =IF(ISBLANK(H2),"NOT PROVIDED",IF(H2<3,"POOR",IF(H2<4.5,"AVERAGE","EXCELLENT"))) -> EXCELLENT | J2: =IF(B2<1000,"LOW PRICE",IF(B2<2000,"MEDIUM PRICE","HIGH PRICE")) -> LOW PRICE
A3: Peacock Throw Pillow Cushion Case For Home Car | B3: 195 | C3: 360 | D3: =C3-B3 -> 165 | E3: 0.46 | F3: =IF(E3<20%,"LOW DISCOUNT",IF(E3<40%,"MEDIUM DISCOUNT","HIGH DISCOUNT")) -> HIGH DISCOUNT | G3: 2 | H3: 5 | I3: =IF(ISBLANK(H3),"NOT PROVIDED",IF(H3<3,"POOR",IF(H3<4.5,"AVERAGE","EXCELLENT"))) -> EXCELLENT | J3: =IF(B3<1000,"LOW PRICE",IF(B3<2000,"MEDIUM PRICE","HIGH PRICE")) -> LOW PRICE
A4: LASA Aluminum Folding Truck Hand Cart - 68kg Max | B4: 2025 | C4: 3971 | D4: =C4-B4 -> 1946 | E4: 0.49 | F4: =IF(E4<20%,"LOW DISCOUNT",IF(E4<40%,"MEDIUM DISCOUNT","HIGH DISCOUNT")) -> HIGH DISCOUNT | G4: 3 | H4: 5 | I4: =IF(ISBLANK(H4),"NOT PROVIDED",IF(H4<3,"POOR",IF(H4<4.5,"AVERAGE","EXCELLENT"))) -> EXCELLENT | J4: =IF(B4<1000,"LOW PRICE",IF(B4<2000,"MEDIUM PRICE","HIGH PRICE")) -> HIGH PRICE
A5: DIY File Folder, Office Drawer File Holder, Pen Holder, Desktop Storage Rack | B5: 1620 | C5: 2690 | D5: =C5-B5 -> 1070 | E5: 0.4 | F5: =IF(E5<20%,"LOW DISCOUNT",IF(E5<40%,"MEDIUM DISCOUNT","HIGH DISCOUNT")) -> HIGH DISCOUNT | G5: 1 | H5: 5 | I5: =IF(ISBLANK(H5),"NOT PROVIDED",IF(H5<3,"POOR",IF(H5<4.5,"AVERAGE","EXCELLENT"))) -> EXCELLENT | J5: =IF(B5<1000,"LOW PRICE",IF(B5<2000,"MEDIUM PRICE","HIGH PRICE")) -> MEDIUM PRICE
A6: Classic Black Cat Cotton Hemp Pillow Case For Home Car | B6: 171 | C6: 360 | D6: =C6-B6 -> 189 | E6: 0.53 | F6: =IF(E6<20%,"LOW DISCOUNT",IF(E6<40%,"MEDIUM DISCOUNT","HIGH DISCOUNT")) -> HIGH DISCOUNT | G6: 2 | H6: 5 | I6: =IF(ISBLANK(H6),"NOT PROVIDED",IF(H6<3,"POOR",IF(H6<4.5,"AVERAGE","EXCELLENT"))) -> EXCELLENT | J6: =IF(B6<1000,"LOW PRICE",IF(B6<2000,"MEDIUM PRICE","HIGH PRICE")) -> LOW PRICE
A7: Bedroom Simple Floor Hanging Clothes Rack Single Pole Hat Rack - White | B7: 979 | C7: 1920 | D7: =C7-B7 -> 941 | E7: 0.49 | F7: =IF(E7<20%,"LOW DISCOUNT",IF(E7<40%,"MEDIUM DISCOUNT","HIGH DISCOUNT")) -> HIGH DISCOUNT | G7: 1 | H7: 5 | I7: =IF(ISBLANK(H7),"NOT PROVIDED",IF(H7<3,"POOR",IF(H7<4.5,"AVERAGE","EXCELLENT"))) -> EXCELLENT | J7: =IF(B7<1000,"LOW PRICE",IF(B7<2000,"MEDIUM PRICE","HIGH PRICE")) -> LOW PRICE
A8: Konka Healty Electric Kettle, 24-hour Heat Preservation,1.5L,800W, White | B8: 3640 | C8: 4588 | D8: =C8-B8 -> 948 | E8: 0.21 | F8: =IF(E8<20%,"LOW DISCOUNT",IF(E8<40%,"MEDIUM DISCOUNT","HIGH DISCOUNT")) -> MEDIUM DISCOUNT | G8: 1 | H8: 5 | I8: =IF(ISBLANK(H8),"NOT PROVIDED",IF(H8<3,"POOR",IF(H8<4.5,"AVERAGE","EXCELLENT"))) -> EXCELLENT | J8: =IF(B8<1000,"LOW PRICE",IF(B8<2000,"MEDIUM PRICE","HIGH PRICE")) -> HIGH PRICE
A9: Portable Home Small Air Humidifier 3-Speed Fan - Green | B9: 1740 | C9: 2356 | D9: =C9-B9 -> 616 | E9: 0.26 | F9: =IF(E9<20%,"LOW DISCOUNT",IF(E9<40%,"MEDIUM DISCOUNT","HIGH DISCOUNT")) -> MEDIUM DISCOUNT | G9: 5 | H9: 4.8 | I9: =IF(ISBLANK(H9),"NOT PROVIDED",IF(H9<3,"POOR",IF(H9<4.5,"AVERAGE","EXCELLENT"))) -> EXCELLENT | J9: =IF(B9<1000,"LOW PRICE",IF(B9<2000,"MEDIUM PRICE","HIGH PRICE")) -> MEDIUM PRICE
A10: LASA FOLDING TABLE SERVING STAND | B10: 1274 | C10: 2800 | D10: =C10-B10 -> 1526 | E10: 0.55 | F10: =IF(E10<20%,"LOW DISCOUNT",IF(E10<40%,"MEDIUM DISCOUNT","HIGH DISCOUNT")) -> HIGH DISCOUNT | G10: 5 | H10: 4.8 | I10: =IF(ISBLANK(H10),"NOT PROVIDED",IF(H10<3,"POOR",IF(H10<4.5,"AVERAGE","EXCELLENT"))) -> EXCELLENT | J10: =IF(B10<1000,"LOW PRICE",IF(B10<2000,"MEDIUM PRICE","HIGH PRICE")) -> MEDIUM PRICE
A11: 40cm Gold DIY Acrylic Wall Sticker Clock | B11: 552 | C11: 1035 | D11: =C11-B11 -> 483 | E11: 0.47 | F11: =IF(E11<20%,"LOW DISCOUNT",IF(E11<40%,"MEDIUM DISCOUNT","HIGH DISCOUNT")) -> HIGH DISCOUNT | G11: 12 | H11: 4.8 | I11: =IF(ISBLANK(H11),"NOT PROVIDED",IF(H11<3,"POOR",IF(H11<4.5,"AVERAGE","EXCELLENT"))) -> EXCELLENT | J11: =IF(B11<1000,"LOW PRICE",IF(B11<2000,"MEDIUM PRICE","HIGH PRICE")) -> LOW PRICE
A12: Weighing Scale Digital Bathroom Body Fat Scale USB-Black | B12: 1580 | C12: 2499 | D12: =C12-B12 -> 919 | E12: 0.37 | F12: =IF(E12<20%,"LOW DISCOUNT",IF(E12<40%,"MEDIUM DISCOUNT","HIGH DISCOUNT")) -> MEDIUM DISCOUNT | G12: 7 | H12: 4.7 | I12: =IF(ISBLANK(H12),"NOT PROVIDED",IF(H12<3,"POOR",IF(H12<4.5,"AVERAGE","EXCELLENT"))) -> EXCELLENT | J12: =IF(B12<1000,"LOW PRICE",IF(B12<2000,"MEDIUM PRICE","HIGH PRICE")) -> MEDIUM PRICE
A13: 100 Pcs Crochet Hook Tool Set Knitting Hook Set With Box | B13: 990 | C13: 1500 | D13: =C13-B13 -> 510 | E13: 0.34 | F13: =IF(E13<20%,"LOW DISCOUNT",IF(E13<40%,"MEDIUM DISCOUNT","HIGH DISCOUNT")) -> MEDIUM DISCOUNT | G13: 39 | H13: 4.7 | I13: =IF(ISBLANK(H13),"NOT PROVIDED",IF(H13<3,"POOR",IF(H13<4.5,"AVERAGE","EXCELLENT"))) -> EXCELLENT | J13: =IF(B13<1000,"LOW PRICE",IF(B13<2000,"MEDIUM PRICE","HIGH PRICE")) -> LOW PRICE
... A58: Wall-mounted Sticker Punch-free Plug Fixer | B58: 450 | C58: 900 | D58: =C58-B58 -> 450 | E58: 0.5 | F58: =IF(E58<20%,"LOW DISCOUNT",IF(E58<40%,"MEDIUM DISCOUNT","HIGH DISCOUNT")) -> HIGH DISCOUNT | G58: 1 | H58: 2 | I58: =IF(ISBLANK(H58),"NOT PROVIDED",IF(H58<3,"POOR",IF(H58<4.5,"AVERAGE","EXCELLENT"))) -> POOR | J58: =IF(B58<1000,"LOW PRICE",IF(B58<2000,"MEDIUM PRICE","HIGH PRICE")) -> LOW PRICE
A59: 4pcs Bathroom/Kitchen Towel Rack,Roll Paper Holder,Towel Bars,Hook | B59: 1860 | C59: 3220 | D59: =C59-B59 -> 1360 | E59: 0.42 | F59: =IF(E59<20%,"LOW DISCOUNT",IF(E59<40%,"MEDIUM DISCOUNT","HIGH DISCOUNT")) -> HIGH DISCOUNT | I59: =IF(ISBLANK(H59),"NOT PROVIDED",IF(H59<3,"POOR",IF(H59<4.5,"AVERAGE","EXCELLENT"))) -> NOT PROVIDED | J59: =IF(B59<1000,"LOW PRICE",IF(B59<2000,"MEDIUM PRICE","HIGH PRICE")) -> MEDIUM PRICE
A60: MultiFunctional Storage Rack Multi-layer Bookshelf | B60: 2200 | C60: 4080 | D60: =C60-B60 -> 1880 | E60: 0.46 | F60: =IF(E60<20%,"LOW DISCOUNT",IF(E60<40%,"MEDIUM DISCOUNT","HIGH DISCOUNT")) -> HIGH DISCOUNT | I60: =IF(ISBLANK(H60),"NOT PROVIDED",IF(H60<3,"POOR",IF(H60<4.5,"AVERAGE","EXCELLENT"))) -> NOT PROVIDED | J60: =IF(B60<1000,"LOW PRICE",IF(B60<2000,"MEDIUM PRICE","HIGH PRICE")) -> HIGH PRICE
A61: Home Decor Chair Cover-Grey | B61: 1980 | C61: 3200 | D61: =C61-B61 -> 1220 | E61: 0.38 | F61: =IF(E61<20%,"LOW DISCOUNT",IF(E61<40%,"MEDIUM DISCOUNT","HIGH DISCOUNT")) -> MEDIUM DISCOUNT | I61: =IF(ISBLANK(H61),"NOT PROVIDED",IF(H61<3,"POOR",IF(H61<4.5,"AVERAGE","EXCELLENT"))) -> NOT PROVIDED | J61: =IF(B61<1000,"LOW PRICE",IF(B61<2000,"MEDIUM PRICE","HIGH PRICE")) -> MEDIUM PRICE
A62: LASA Stainless Steel Double Wall Mount Soap Dispenser - 500ml | B62: 2750 | C62: 4471 | D62: =C62-B62 -> 1721 | E62: 0.38 | F62: =IF(E62<20%,"LOW DISCOUNT",IF(E62<40%,"MEDIUM DISCOUNT","HIGH DISCOUNT")) -> MEDIUM DISCOUNT | I62: =IF(ISBLANK(H62),"NOT PROVIDED",IF(H62<3,"POOR",IF(H62<4.5,"AVERAGE","EXCELLENT"))) -> NOT PROVIDED | J62: =IF(B62<1000,"LOW PRICE",IF(B62<2000,"MEDIUM PRICE","HIGH PRICE")) -> HIGH PRICE
A63: 4M Float Switch Water Level Controller -Water Tank | B63: 475 | C63: 931 | D63: =C63-B63 -> 456 | E63: 0.49 | F63: =IF(E63<20%,"LOW DISCOUNT",IF(E63<40%,"MEDIUM DISCOUNT","HIGH DISCOUNT")) -> HIGH DISCOUNT | I63: =IF(ISBLANK(H63),"NOT PROVIDED",IF(H63<3,"POOR",IF(H63<4.5,"AVERAGE","EXCELLENT"))) -> NOT PROVIDED | J63: =IF(B63<1000,"LOW PRICE",IF(B63<2000,"MEDIUM PRICE","HIGH PRICE")) -> LOW PRICE
A64: Modern Sofa Throw Pillow Cover-45x45cm-Blue&Red | B64: 238 | C64: 476 | D64: =C64-B64 -> 238 | E64: 0.5 | F64: =IF(E64<20%,"LOW DISCOUNT",IF(E64<40%,"MEDIUM DISCOUNT","HIGH DISCOUNT")) -> HIGH DISCOUNT | I64: =IF(ISBLANK(H64),"NOT PROVIDED",IF(H64<3,"POOR",IF(H64<4.5,"AVERAGE","EXCELLENT"))) -> NOT PROVIDED | J64: =IF(B64<1000,"LOW PRICE",IF(B64<2000,"MEDIUM PRICE","HIGH PRICE")) -> LOW PRICE
A65: Balloon Insert, Birthday Party Balloon Set, PU Leather | B65: 610 | C65: 1060 | D65: =C65-B65 -> 450 | E65: 0.42 | F65: =IF(E65<20%,"LOW DISCOUNT",IF(E65<40%,"MEDIUM DISCOUNT","HIGH DISCOUNT")) -> HIGH DISCOUNT | I65: =IF(ISBLANK(H65),"NOT PROVIDED",IF(H65<3,"POOR",IF(H65<4.5,"AVERAGE","EXCELLENT"))) -> NOT PROVIDED | J65: =IF(B65<1000,"LOW PRICE",IF(B65<2000,"MEDIUM PRICE","HIGH PRICE")) -> LOW PRICE
A66: Shower Cap Wide Elastic Band Cover Reusable Bashroom Cap | B66: 2132 | C66: 2169 | D66: =C66-B66 -> 37 | E66: 0.02 | F66: =IF(E66<20%,"LOW DISCOUNT",IF(E66<40%,"MEDIUM DISCOUNT","HIGH DISCOUNT")) -> LOW DISCOUNT | I66: =IF(ISBLANK(H66),"NOT PROVIDED",IF(H66<3,"POOR",IF(H66<4.5,"AVERAGE","EXCELLENT"))) -> NOT PROVIDED | J66: =IF(B66<1000,"LOW PRICE",IF(B66<2000,"MEDIUM PRICE","HIGH PRICE")) -> HIGH PRICE
A67: Christmas Elk Fence Yard Lawn Decorations Cute For Holidays | B67: 999 | C67: 2000 | D67: =C67-B67 -> 1001 | E67: 0.5 | F67: =IF(E67<20%,"LOW DISCOUNT",IF(E67<40%,"MEDIUM DISCOUNT","HIGH DISCOUNT")) -> HIGH DISCOUNT | I67: =IF(ISBLANK(H67),"NOT PROVIDED",IF(H67<3,"POOR",IF(H67<4.5,"AVERAGE","EXCELLENT"))) -> NOT PROVIDED | J67: =IF(B67<1000,"LOW PRICE",IF(B67<2000,"MEDIUM PRICE","HIGH PRICE")) -> LOW PRICE
A68: 60W Hot Melt Glue Sprayer - Efficient And Stable Glue Dispensing | B68: 1190 | C68: 1785 | D68: =C68-B68 -> 595 | E68: 0.33 | F68: =IF(E68<20%,"LOW DISCOUNT",IF(E68<40%,"MEDIUM DISCOUNT","HIGH DISCOUNT")) -> MEDIUM DISCOUNT | I68: =IF(ISBLANK(H68),"NOT PROVIDED",IF(H68<3,"POOR",IF(H68<4.5,"AVERAGE","EXCELLENT"))) -> NOT PROVIDED | J68: =IF(B68<1000,"LOW PRICE",IF(B68<2000,"MEDIUM PRICE","HIGH PRICE")) -> MEDIUM PRICE
A69: Car Phone Charging Stand | B69: 671 | C69: 1316 | D69: =C69-B69 -> 645 | E69: 0.49 | F69: =IF(E69<20%,"LOW DISCOUNT",IF(E69<40%,"MEDIUM DISCOUNT","HIGH DISCOUNT")) -> HIGH DISCOUNT | I69: =IF(ISBLANK(H69),"NOT PROVIDED",IF(H69<3,"POOR",IF(H69<4.5,"AVERAGE","EXCELLENT"))) -> NOT PROVIDED | J69: =IF(B69<1000,"LOW PRICE",IF(B69<2000,"MEDIUM PRICE","HIGH PRICE")) -> LOW PRICE
A70: 2pcs Solar Street Light Flood Light Outdoor | B70: 1200 | C70: 1950 | D70: =C70-B70 -> 750 | E70: 0.38 | F70: =IF(E70<20%,"LOW DISCOUNT",IF(E70<40%,"MEDIUM DISCOUNT","HIGH DISCOUNT")) -> MEDIUM DISCOUNT | I70: =IF(ISBLANK(H70),"NOT PROVIDED",IF(H70<3,"POOR",IF(H70<4.5,"AVERAGE","EXCELLENT"))) -> NOT PROVIDED | J70: =IF(B70<1000,"LOW PRICE",IF(B70<2000,"MEDIUM PRICE","HIGH PRICE")) -> MEDIUM PRICE
... A114: Black Simple Water Cup Wine Coaster Anti Slip Absorbent | B114: 169 | C114: 320 | D114: =C114-B114 -> 151 | E114: 0.47 | F114: =IF(E114<20%,"LOW DISCOUNT",IF(E114<40%,"MEDIUM DISCOUNT","HIGH DISCOUNT")) -> HIGH DISCOUNT | I114: =IF(ISBLANK(H114),"NOT PROVIDED",IF(H114<3,"POOR",IF(H114<4.5,"AVERAGE","EXCELLENT"))) -> NOT PROVIDED | J114: =IF(B114<1000,"LOW PRICE",IF(B114<2000,"MEDIUM PRICE","HIGH PRICE")) -> LOW PRICE

Sheet TOP 10 BY NUMBER OF REVIEWS
A1: Product | B1: Current price | C1: Old price | D1: Discount Price | E1: Discount | F1: Discount category | G1: Review | H1: Ratingd | I1: Rating Category | J1: Price Category
A2: 115 Piece Set Of Multifunctional Precision Screwdrivers | B2: 950 | C2: 1525 | D2: =C2-B2 -> 575 | E2: 0.38 | F2: =IF(E2<20%,"LOW DISCOUNT",IF(E2<40%,"MEDIUM DISCOUNT","HIGH DISCOUNT")) -> MEDIUM DISCOUNT | G2: 2 | H2: 4.5 | I2: =IF(ISBLANK(H2),"NOT PROVIDED",IF(H2<3,"POOR",IF(H2<4.5,"AVERAGE","EXCELLENT"))) -> EXCELLENT | J2: =IF(B2<1000,"LOW PRICE",IF(B2<2000,"MEDIUM PRICE","HIGH PRICE")) -> LOW PRICE
A3: Metal Decorative Hooks Key Hangers Entryway Wall Hooks Towel Hooks - Home | B3: 527 | C3: 999 | D3: =C3-B3 -> 472 | E3: 0.47 | F3: =IF(E3<20%,"LOW DISCOUNT",IF(E3<40%,"MEDIUM DISCOUNT","HIGH DISCOUNT")) -> HIGH DISCOUNT | G3: 14 | H3: 4.1 | I3: =IF(ISBLANK(H3),"NOT PROVIDED",IF(H3<3,"POOR",IF(H3<4.5,"AVERAGE","EXCELLENT"))) -> AVERAGE | J3: =IF(B3<1000,"LOW PRICE",IF(B3<2000,"MEDIUM PRICE","HIGH PRICE")) -> LOW PRICE
A4: Portable Mini Cordless Car Vacuum Cleaner - Blue | B4: 2199 | C4: 2923 | D4: =C4-B4 -> 724 | E4: 0.25 | F4: =IF(E4<20%,"LOW DISCOUNT",IF(E4<40%,"MEDIUM DISCOUNT","HIGH DISCOUNT")) -> MEDIUM DISCOUNT | G4: 24 | H4: 4.6 | I4: =IF(ISBLANK(H4),"NOT PROVIDED",IF(H4<3,"POOR",IF(H4<4.5,"AVERAGE","EXCELLENT"))) -> EXCELLENT | J4: =IF(B4<1000,"LOW PRICE",IF(B4<2000,"MEDIUM PRICE","HIGH PRICE")) -> HIGH PRICE
A5: Weighing Scale Digital Bathroom Body Fat Scale USB-Black | B5: 1580 | C5: 2499 | D5: =C5-B5 -> 919 | E5: 0.37 | F5: =IF(E5<20%,"LOW DISCOUNT",IF(E5<40%,"MEDIUM DISCOUNT","HIGH DISCOUNT")) -> MEDIUM DISCOUNT | G5: 7 | H5: 4.7 | I5: =IF(ISBLANK(H5),"NOT PROVIDED",IF(H5<3,"POOR",IF(H5<4.5,"AVERAGE","EXCELLENT"))) -> EXCELLENT | J5: =IF(B5<1000,"LOW PRICE",IF(B5<2000,"MEDIUM PRICE","HIGH PRICE")) -> MEDIUM PRICE
A6: Portable Home Small Air Humidifier 3-Speed Fan - Green | B6: 1740 | C6: 2356 | D6: =C6-B6 -> 616 | E6: 0.26 | F6: =IF(E6<20%,"LOW DISCOUNT",IF(E6<40%,"MEDIUM DISCOUNT","HIGH DISCOUNT")) -> MEDIUM DISCOUNT | G6: 5 | H6: 4.8 | I6: =IF(ISBLANK(H6),"NOT PROVIDED",IF(H6<3,"POOR",IF(H6<4.5,"AVERAGE","EXCELLENT"))) -> EXCELLENT | J6: =IF(B6<1000,"LOW PRICE",IF(B6<2000,"MEDIUM PRICE","HIGH PRICE")) -> MEDIUM PRICE
A7: 220V 60W Electric Soldering Iron Kits With Tools, Tips, And Multimeter | B7: 2999 | C7: 3290 | D7: =C7-B7 -> 291 | E7: 0.09 | F7: =IF(E7<20%,"LOW DISCOUNT",IF(E7<40%,"MEDIUM DISCOUNT","HIGH DISCOUNT")) -> LOW DISCOUNT | G7: 15 | H7: 4 | I7: =IF(ISBLANK(H7),"NOT PROVIDED",IF(H7<3,"POOR",IF(H7<4.5,"AVERAGE","EXCELLENT"))) -> AVERAGE | J7: =IF(B7<1000,"LOW PRICE",IF(B7<2000,"MEDIUM PRICE","HIGH PRICE")) -> HIGH PRICE
A8: 137 Pieces Cake Decorating Tool Set Baking Supplies | B8: 2319 | C8: 3032 | D8: =C8-B8 -> 713 | E8: 0.24 | F8: =IF(E8<20%,"LOW DISCOUNT",IF(E8<40%,"MEDIUM DISCOUNT","HIGH DISCOUNT")) -> MEDIUM DISCOUNT | G8: 55 | H8: 4.6 | I8: =IF(ISBLANK(H8),"NOT PROVIDED",IF(H8<3,"POOR",IF(H8<4.5,"AVERAGE","EXCELLENT"))) -> EXCELLENT | J8: =IF(B8<1000,"LOW PRICE",IF(B8<2000,"MEDIUM PRICE","HIGH PRICE")) -> HIGH PRICE
A9: Desk Foldable Fan Adjustable Fan Strong Wind 3 Gear Usb | B9: 988 | C9: 1580 | D9: =C9-B9 -> 592 | E9: 0.37 | F9: =IF(E9<20%,"LOW DISCOUNT",IF(E9<40%,"MEDIUM DISCOUNT","HIGH DISCOUNT")) -> MEDIUM DISCOUNT | G9: 2 | H9: 4 | I9: =IF(ISBLANK(H9),"NOT PROVIDED",IF(H9<3,"POOR",IF(H9<4.5,"AVERAGE","EXCELLENT"))) -> AVERAGE | J9: =IF(B9<1000,"LOW PRICE",IF(B9<2000,"MEDIUM PRICE","HIGH PRICE")) -> LOW PRICE
A10: LASA FOLDING TABLE SERVING STAND | B10: 1274 | C10: 2800 | D10: =C10-B10 -> 1526 | E10: 0.55 | F10: =IF(E10<20%,"LOW DISCOUNT",IF(E10<40%,"MEDIUM DISCOUNT","HIGH DISCOUNT")) -> HIGH DISCOUNT | G10: 5 | H10: 4.8 | I10: =IF(ISBLANK(H10),"NOT PROVIDED",IF(H10<3,"POOR",IF(H10<4.5,"AVERAGE","EXCELLENT"))) -> EXCELLENT | J10: =IF(B10<1000,"LOW PRICE",IF(B10<2000,"MEDIUM PRICE","HIGH PRICE")) -> MEDIUM PRICE
A11: 13 In 1 Home Repair Tools Box Kit Set | B11: 1600 | C11: 2929 | D11: =C11-B11 -> 1329 | E11: 0.45 | F11: =IF(E11<20%,"LOW DISCOUNT",IF(E11<40%,"MEDIUM DISCOUNT","HIGH DISCOUNT")) -> HIGH DISCOUNT | G11: 5 | H11: 3.8 | I11: =IF(ISBLANK(H11),"NOT PROVIDED",IF(H11<3,"POOR",IF(H11<4.5,"AVERAGE","EXCELLENT"))) -> AVERAGE | J11: =IF(B11<1000,"LOW PRICE",IF(B11<2000,"MEDIUM PRICE","HIGH PRICE")) -> MEDIUM PRICE
A12: Genebre 115 In 1 Screwdriver Repairing Tool Set For IPhone Cellphone Hand Tool | B12: 799 | C12: 999 | D12: =C12-B12 -> 200 | E12: 0.2 | F12: =IF(E12<20%,"LOW DISCOUNT",IF(E12<40%,"MEDIUM DISCOUNT","HIGH DISCOUNT")) -> MEDIUM DISCOUNT | G12: 12 | H12: 4.1 | I12: =IF(ISBLANK(H12),"NOT PROVIDED",IF(H12<3,"POOR",IF(H12<4.5,"AVERAGE","EXCELLENT"))) -> AVERAGE | J12: =IF(B12<1000,"LOW PRICE",IF(B12<2000,"MEDIUM PRICE","HIGH PRICE")) -> LOW PRICE
A13: 100 Pcs Crochet Hook Tool Set Knitting Hook Set With Box | B13: 990 | C13: 1500 | D13: =C13-B13 -> 510 | E13: 0.34 | F13: =IF(E13<20%,"LOW DISCOUNT",IF(E13<40%,"MEDIUM DISCOUNT","HIGH DISCOUNT")) -> MEDIUM DISCOUNT | G13: 39 | H13: 4.7 | I13: =IF(ISBLANK(H13),"NOT PROVIDED",IF(H13<3,"POOR",IF(H13<4.5,"AVERAGE","EXCELLENT"))) -> EXCELLENT | J13: =IF(B13<1000,"LOW PRICE",IF(B13<2000,"MEDIUM PRICE","HIGH PRICE")) -> LOW PRICE
... A22: 3PCS Single Head Knitting Crochet Sweater Needle Set | B22: 38 | C22: 80 | D22: =C22-B22 -> 42 | E22: 0.53 | F22: =IF(E22<20%,"LOW DISCOUNT",IF(E22<40%,"MEDIUM DISCOUNT","HIGH DISCOUNT")) -> HIGH DISCOUNT | G22: 13 | H22: 3.3 | I22: =IF(ISBLANK(H22),"NOT PROVIDED",IF(H22<3,"POOR",IF(H22<4.5,"AVERAGE","EXCELLENT"))) -> AVERAGE | J22: =IF(B22<1000,"LOW PRICE",IF(B22<2000,"MEDIUM PRICE","HIGH PRICE")) -> LOW PRICE
A23: 4pcs Bathroom/Kitchen Towel Rack,Roll Paper Holder,Towel Bars,Hook | B23: 1860 | C23: 3220 | D23: =C23-B23 -> 1360 | E23: 0.42 | F23: =IF(E23<20%,"LOW DISCOUNT",IF(E23<40%,"MEDIUM DISCOUNT","HIGH DISCOUNT")) -> HIGH DISCOUNT | I23: =IF(ISBLANK(H23),"NOT PROVIDED",IF(H23<3,"POOR",IF(H23<4.5,"AVERAGE","EXCELLENT"))) -> NOT PROVIDED | J23: =IF(B23<1000,"LOW PRICE",IF(B23<2000,"MEDIUM PRICE","HIGH PRICE")) -> MEDIUM PRICE
A24: LED Romantic Spaceship Starry Sky Projector,Children's Bedroom Night Light-Blue | B24: 880 | C24: 1350 | D24: =C24-B24 -> 470 | E24: 0.35 | F24: =IF(E24<20%,"LOW DISCOUNT",IF(E24<40%,"MEDIUM DISCOUNT","HIGH DISCOUNT")) -> MEDIUM DISCOUNT | G24: 6 | H24: 4 | I24: =IF(ISBLANK(H24),"NOT PROVIDED",IF(H24<3,"POOR",IF(H24<4.5,"AVERAGE","EXCELLENT"))) -> AVERAGE | J24: =IF(B24<1000,"LOW PRICE",IF(B24<2000,"MEDIUM PRICE","HIGH PRICE")) -> LOW PRICE
A25: Foldable Overbed Table/Desk | B25: 1650 | C25: 2150 | D25: =C25-B25 -> 500 | E25: 0.23 | F25: =IF(E25<20%,"LOW DISCOUNT",IF(E25<40%,"MEDIUM DISCOUNT","HIGH DISCOUNT")) -> MEDIUM DISCOUNT | G25: 14 | H25: 4.4 | I25: =IF(ISBLANK(H25),"NOT PROVIDED",IF(H25<3,"POOR",IF(H25<4.5,"AVERAGE","EXCELLENT"))) -> AVERAGE | J25: =IF(B25<1000,"LOW PRICE",IF(B25<2000,"MEDIUM PRICE","HIGH PRICE")) -> MEDIUM PRICE
A26: LASA 3 Tier Bamboo Shoe Bench Storage Shelf | B26: 2048 | C26: 4500 | D26: =C26-B26 -> 2452 | E26: 0.54 | F26: =IF(E26<20%,"LOW DISCOUNT",IF(E26<40%,"MEDIUM DISCOUNT","HIGH DISCOUNT")) -> HIGH DISCOUNT | G26: 7 | H26: 4.3 | I26: =IF(ISBLANK(H26),"NOT PROVIDED",IF(H26<3,"POOR",IF(H26<4.5,"AVERAGE","EXCELLENT"))) -> AVERAGE | J26: =IF(B26<1000,"LOW PRICE",IF(B26<2000,"MEDIUM PRICE","HIGH PRICE")) -> HIGH PRICE
A27: Electronic Digital Display Vernier Caliper | B27: 420 | C27: 647 | D27: =C27-B27 -> 227 | E27: 0.35 | F27: =IF(E27<20%,"LOW DISCOUNT",IF(E27<40%,"MEDIUM DISCOUNT","HIGH DISCOUNT")) -> MEDIUM DISCOUNT | G27: 49 | H27: 4.6 | I27: =IF(ISBLANK(H27),"NOT PROVIDED",IF(H27<3,"POOR",IF(H27<4.5,"AVERAGE","EXCELLENT"))) -> EXCELLENT | J27: =IF(B27<1000,"LOW PRICE",IF(B27<2000,"MEDIUM PRICE","HIGH PRICE")) -> LOW PRICE
A28: Portable Wardrobe Nonwoven With 3 Hanging Rods And 6 Storage Shelves | B28: 2880 | C28: 3520 | D28: =C28-B28 -> 640 | E28: 0.18 | F28: =IF(E28<20%,"LOW DISCOUNT",IF(E28<40%,"MEDIUM DISCOUNT","HIGH DISCOUNT")) -> LOW DISCOUNT | G28: 12 | H28: 3.8 | I28: =IF(ISBLANK(H28),"NOT PROVIDED",IF(H28<3,"POOR",IF(H28<4.5,"AVERAGE","EXCELLENT"))) -> AVERAGE | J28: =IF(B28<1000,"LOW PRICE",IF(B28<2000,"MEDIUM PRICE","HIGH PRICE")) -> HIGH PRICE
A29: 12 Litre Black Insulated Lunch Box | B29: 1350 | C29: 1990 | D29: =C29-B29 -> 640 | E29: 0.32 | F29: =IF(E29<20%,"LOW DISCOUNT",IF(E29<40%,"MEDIUM DISCOUNT","HIGH DISCOUNT")) -> MEDIUM DISCOUNT | G29: 13 | H29: 3.8 | I29: =IF(ISBLANK(H29),"NOT PROVIDED",IF(H29<3,"POOR",IF(H29<4.5,"AVERAGE","EXCELLENT"))) -> AVERAGE | J29: =IF(B29<1000,"LOW PRICE",IF(B29<2000,"MEDIUM PRICE","HIGH PRICE")) -> MEDIUM PRICE
A30: 52 Pieces Cake Decorating Tool Set Gift Kit Baking Supplies | B30: 1758 | C30: 2499 | D30: =C30-B30 -> 741 | E30: 0.3 | F30: =IF(E30<20%,"LOW DISCOUNT",IF(E30<40%,"MEDIUM DISCOUNT","HIGH DISCOUNT")) -> MEDIUM DISCOUNT | G30: 20 | H30: 4.1 | I30: =IF(ISBLANK(H30),"NOT PROVIDED",IF(H30<3,"POOR",IF(H30<4.5,"AVERAGE","EXCELLENT"))) -> AVERAGE | J30: =IF(B30<1000,"LOW PRICE",IF(B30<2000,"MEDIUM PRICE","HIGH PRICE")) -> MEDIUM PRICE
A31: MultiFunctional Storage Rack Multi-layer Bookshelf | B31: 2200 | C31: 4080 | D31: =C31-B31 -> 1880 | E31: 0.46 | F31: =IF(E31<20%,"LOW DISCOUNT",IF(E31<40%,"MEDIUM DISCOUNT","HIGH DISCOUNT")) -> HIGH DISCOUNT | I31: =IF(ISBLANK(H31),"NOT PROVIDED",IF(H31<3,"POOR",IF(H31<4.5,"AVERAGE","EXCELLENT"))) -> NOT PROVIDED | J31: =IF(B31<1000,"LOW PRICE",IF(B31<2000,"MEDIUM PRICE","HIGH PRICE")) -> HIGH PRICE
A32: Exfoliate And Exfoliate Face Towel - Black | B32: 185 | C32: 382 | D32: =C32-B32 -> 197 | E32: 0.52 | F32: =IF(E32<20%,"LOW DISCOUNT",IF(E32<40%,"MEDIUM DISCOUNT","HIGH DISCOUNT")) -> HIGH DISCOUNT | G32: 9 | H32: 4.3 | I32: =IF(ISBLANK(H32),"NOT PROVIDED",IF(H32<3,"POOR",IF(H32<4.5,"AVERAGE","EXCELLENT"))) -> AVERAGE | J32: =IF(B32<1000,"LOW PRICE",IF(B32<2000,"MEDIUM PRICE","HIGH PRICE")) -> LOW PRICE
A33: 12 Litre Insulated Lunch Box Grey | B33: 980 | C33: 1490 | D33: =C33-B33 -> 510 | E33: 0.34 | F33: =IF(E33<20%,"LOW DISCOUNT",IF(E33<40%,"MEDIUM DISCOUNT","HIGH DISCOUNT")) -> MEDIUM DISCOUNT | G33: 12 | H33: 4.7 | I33: =IF(ISBLANK(H33),"NOT PROVIDED",IF(H33<3,"POOR",IF(H33<4.5,"AVERAGE","EXCELLENT"))) -> EXCELLENT | J33: =IF(B33<1000,"LOW PRICE",IF(B33<2000,"MEDIUM PRICE","HIGH PRICE")) -> LOW PRICE
A34: LED Eye Protection Desk Lamp , Study, Reading, USB Fan - Double Pen Holder | B34: 1820 | C34: 3490 | D34: =C34-B34 -> 1670 | E34: 0.48 | F34: =IF(E34<20%,"LOW DISCOUNT",IF(E34<40%,"MEDIUM DISCOUNT","HIGH DISCOUNT")) -> HIGH DISCOUNT | G34: 9 | H34: 4.3 | I34: =IF(ISBLANK(H34),"NOT PROVIDED",IF(H34<3,"POOR",IF(H34<4.5,"AVERAGE","EXCELLENT"))) -> AVERAGE | J34: =IF(B34<1000,"LOW PRICE",IF(B34<2000,"MEDIUM PRICE","HIGH PRICE")) -> MEDIUM PRICE
A35: 53Pcs/Set Yarn Knitting Crochet Hooks With Bag - Fortune Cat | B35: 1940 | C35: 2650 | D35: =C35-B35 -> 710 | E35: 0.27 | F35: =IF(E35<20%,"LOW DISCOUNT",IF(E35<40%,"MEDIUM DISCOUNT","HIGH DISCOUNT")) -> MEDIUM DISCOUNT | G35: 20 | H35: 4.7 | I35: =IF(ISBLANK(H35),"NOT PROVIDED",IF(H35<3,"POOR",IF(H35<4.5,"AVERAGE","EXCELLENT"))) -> EXCELLENT | J35: =IF(B35<1000,"LOW PRICE",IF(B35<2000,"MEDIUM PRICE","HIGH PRICE")) -> MEDIUM PRICE
A36: 53 Pieces/Set Yarn Knitting Crochet Hooks With Bag - Pansies | B36: 1980 | C36: 2699 | D36: =C36-B36 -> 719 | E36: 0.27 | F36: =IF(E36<20%,"LOW DISCOUNT",IF(E36<40%,"MEDIUM DISCOUNT","HIGH DISCOUNT")) -> MEDIUM DISCOUNT | G36: 32 | H36: 4.5 | I36: =IF(ISBLANK(H36),"NOT PROVIDED",IF(H36<3,"POOR",IF(H36<4.5,"AVERAGE","EXCELLENT"))) -> EXCELLENT | J36: =IF(B36<1000,"LOW PRICE",IF(B36<2000,"MEDIUM PRICE","HIGH PRICE")) -> MEDIUM PRICE
A37: DIY File Folder, Office Drawer File Holder, Pen Holder, Desktop Storage Rack | B37: 1620 | C37: 2690 | D37: =C37-B37 -> 1070 | E37: 0.4 | F37: =IF(E37<20%,"LOW DISCOUNT",IF(E37<40%,"MEDIUM DISCOUNT","HIGH DISCOUNT")) -> HIGH DISCOUNT | G37: 1 | H37: 5 | I37: =IF(ISBLANK(H37),"NOT PROVIDED",IF(H37<3,"POOR",IF(H37<4.5,"AVERAGE","EXCELLENT"))) -> EXCELLENT | J37: =IF(B37<1000,"LOW PRICE",IF(B37<2000,"MEDIUM PRICE","HIGH PRICE")) -> MEDIUM PRICE
A38: Classic Black Cat Cotton Hemp Pillow Case For Home Car | B38: 171 | C38: 360 | D38: =C38-B38 -> 189 | E38: 0.53 | F38: =IF(E38<20%,"LOW DISCOUNT",IF(E38<40%,"MEDIUM DISCOUNT","HIGH DISCOUNT")) -> HIGH DISCOUNT | G38: 2 | H38: 5 | I38: =IF(ISBLANK(H38),"NOT PROVIDED",IF(H38<3,"POOR",IF(H38<4.5,"AVERAGE","EXCELLENT"))) -> EXCELLENT | J38: =IF(B38<1000,"LOW PRICE",IF(B38<2000,"MEDIUM PRICE","HIGH PRICE")) -> LOW PRICE
A39: Punch-free Great Load Bearing Bathroom Storage Rack Wall Shelf-White | B39: 389 | C39: 656 | D39: =C39-B39 -> 267 | E39: 0.41 | F39: =IF(E39<20%,"LOW DISCOUNT",IF(E39<40%,"MEDIUM DISCOUNT","HIGH DISCOUNT")) -> HIGH DISCOUNT | G39: 36 | H39: 4.3 | I39: =IF(ISBLANK(H39),"NOT PROVIDED",IF(H39<3,"POOR",IF(H39<4.5,"AVERAGE","EXCELLENT"))) -> AVERAGE | J39: =IF(B39<1000,"LOW PRICE",IF(B39<2000,"MEDIUM PRICE","HIGH PRICE")) -> LOW PRICE
A40: 1/2/3 Seater Elastic Sofa Cover,Living Room | B40: 1620 | C40: 2200 | D40: =C40-B40 -> 580 | E40: 0.26 | F40: =IF(E40<20%,"LOW DISCOUNT",IF(E40<40%,"MEDIUM DISCOUNT","HIGH DISCOUNT")) -> MEDIUM DISCOUNT | G40: 2 | H40: 4.5 | I40: =IF(ISBLANK(H40),"NOT PROVIDED",IF(H40<3,"POOR",IF(H40<4.5,"AVERAGE","EXCELLENT"))) -> EXCELLENT | J40: =IF(B40<1000,"LOW PRICE",IF(B40<2000,"MEDIUM PRICE","HIGH PRICE")) -> MEDIUM PRICE
A41: Home Decor Chair Cover-Grey | B41: 1980 | C41: 3200 | D41: =C41-B41 -> 1220 | E41: 0.38 | F41: =IF(E41<20%,"LOW DISCOUNT",IF(E41<40%,"MEDIUM DISCOUNT","HIGH DISCOUNT")) -> MEDIUM DISCOUNT | I41: =IF(ISBLANK(H41),"NOT PROVIDED",IF(H41<3,"POOR",IF(H41<4.5,"AVERAGE","EXCELLENT"))) -> NOT PROVIDED | J41: =IF(B41<1000,"LOW PRICE",IF(B41<2000,"MEDIUM PRICE","HIGH PRICE")) -> MEDIUM PRICE
A42: LASA Stainless Steel Double Wall Mount Soap Dispenser - 500ml | B42: 2750 | C42: 4471 | D42: =C42-B42 -> 1721 | E42: 0.38 | F42: =IF(E42<20%,"LOW DISCOUNT",IF(E42<40%,"MEDIUM DISCOUNT","HIGH DISCOUNT")) -> MEDIUM DISCOUNT | I42: =IF(ISBLANK(H42),"NOT PROVIDED",IF(H42<3,"POOR",IF(H42<4.5,"AVERAGE","EXCELLENT"))) -> NOT PROVIDED | J42: =IF(B42<1000,"LOW PRICE",IF(B42<2000,"MEDIUM PRICE","HIGH PRICE")) -> HIGH PRICE
A43: 4M Float Switch Water Level Controller -Water Tank | B43: 475 | C43: 931 | D43: =C43-B43 -> 456 | E43: 0.49 | F43: =IF(E43<20%,"LOW DISCOUNT",IF(E43<40%,"MEDIUM DISCOUNT","HIGH DISCOUNT")) -> HIGH DISCOUNT | I43: =IF(ISBLANK(H43),"NOT PROVIDED",IF(H43<3,"POOR",IF(H43<4.5,"AVERAGE","EXCELLENT"))) -> NOT PROVIDED | J43: =IF(B43<1000,"LOW PRICE",IF(B43<2000,"MEDIUM PRICE","HIGH PRICE")) -> LOW PRICE
A44: Modern Sofa Throw Pillow Cover-45x45cm-Blue&Red | B44: 238 | C44: 476 | D44: =C44-B44 -> 238 | E44: 0.5 | F44: =IF(E44<20%,"LOW DISCOUNT",IF(E44<40%,"MEDIUM DISCOUNT","HIGH DISCOUNT")) -> HIGH DISCOUNT | I44: =IF(ISBLANK(H44),"NOT PROVIDED",IF(H44<3,"POOR",IF(H44<4.5,"AVERAGE","EXCELLENT"))) -> NOT PROVIDED | J44: =IF(B44<1000,"LOW PRICE",IF(B44<2000,"MEDIUM PRICE","HIGH PRICE")) -> LOW PRICE
A45: Balloon Insert, Birthday Party Balloon Set, PU Leather | B45: 610 | C45: 1060 | D45: =C45-B45 -> 450 | E45: 0.42 | F45: =IF(E45<20%,"LOW DISCOUNT",IF(E45<40%,"MEDIUM DISCOUNT","HIGH DISCOUNT")) -> HIGH DISCOUNT | I45: =IF(ISBLANK(H45),"NOT PROVIDED",IF(H45<3,"POOR",IF(H45<4.5,"AVERAGE","EXCELLENT"))) -> NOT PROVIDED | J45: =IF(B45<1000,"LOW PRICE",IF(B45<2000,"MEDIUM PRICE","HIGH PRICE")) -> LOW PRICE
A46: Shower Cap Wide Elastic Band Cover Reusable Bashroom Cap | B46: 2132 | C46: 2169 | D46: =C46-B46 -> 37 | E46: 0.02 | F46: =IF(E46<20%,"LOW DISCOUNT",IF(E46<40%,"MEDIUM DISCOUNT","HIGH DISCOUNT")) -> LOW DISCOUNT | I46: =IF(ISBLANK(H46),"NOT PROVIDED",IF(H46<3,"POOR",IF(H46<4.5,"AVERAGE","EXCELLENT"))) -> NOT PROVIDED | J46: =IF(B46<1000,"LOW PRICE",IF(B46<2000,"MEDIUM PRICE","HIGH PRICE")) -> HIGH PRICE
A47: Christmas Elk Fence Yard Lawn Decorations Cute For Holidays | B47: 999 | C47: 2000 | D47: =C47-B47 -> 1001 | E47: 0.5 | F47: =IF(E47<20%,"LOW DISCOUNT",IF(E47<40%,"MEDIUM DISCOUNT","HIGH DISCOUNT")) -> HIGH DISCOUNT | I47: =IF(ISBLANK(H47),"NOT PROVIDED",IF(H47<3,"POOR",IF(H47<4.5,"AVERAGE","EXCELLENT"))) -> NOT PROVIDED | J47: =IF(B47<1000,"LOW PRICE",IF(B47<2000,"MEDIUM PRICE","HIGH PRICE")) -> LOW PRICE
A48: 60W Hot Melt Glue Sprayer - Efficient And Stable Glue Dispensing | B48: 1190 | C48: 1785 | D48: =C48-B48 -> 595 | E48: 0.33 | F48: =IF(E48<20%,"LOW DISCOUNT",IF(E48<40%,"MEDIUM DISCOUNT","HIGH DISCOUNT")) -> MEDIUM DISCOUNT | I48: =IF(ISBLANK(H48),"NOT PROVIDED",IF(H48<3,"POOR",IF(H48<4.5,"AVERAGE","EXCELLENT"))) -> NOT PROVIDED | J48: =IF(B48<1000,"LOW PRICE",IF(B48<2000,"MEDIUM PRICE","HIGH PRICE")) -> MEDIUM PRICE
...

Sheet TOP 10 HIGHEST RATED PRODUCTS
A1: Product | B1: Current price | C1: Old price | D1: Discount Price | E1: Discount | F1: Discount category | G1: Review | H1: Ratingd | I1: Rating Category | J1: Price Category
A2: 115 Piece Set Of Multifunctional Precision Screwdrivers | B2: 950 | C2: 1525 | D2: =C2-B2 -> 575 | E2: 0.38 | F2: =IF(E2<20%,"LOW DISCOUNT",IF(E2<40%,"MEDIUM DISCOUNT","HIGH DISCOUNT")) -> MEDIUM DISCOUNT | G2: 2 | H2: 4.5 | I2: =IF(ISBLANK(H2),"NOT PROVIDED",IF(H2<3,"POOR",IF(H2<4.5,"AVERAGE","EXCELLENT"))) -> EXCELLENT | J2: =IF(B2<1000,"LOW PRICE",IF(B2<2000,"MEDIUM PRICE","HIGH PRICE")) -> LOW PRICE
A3: Metal Decorative Hooks Key Hangers Entryway Wall Hooks Towel Hooks - Home | B3: 527 | C3: 999 | D3: =C3-B3 -> 472 | E3: 0.47 | F3: =IF(E3<20%,"LOW DISCOUNT",IF(E3<40%,"MEDIUM DISCOUNT","HIGH DISCOUNT")) -> HIGH DISCOUNT | G3: 14 | H3: 4.1 | I3: =IF(ISBLANK(H3),"NOT PROVIDED",IF(H3<3,"POOR",IF(H3<4.5,"AVERAGE","EXCELLENT"))) -> AVERAGE | J3: =IF(B3<1000,"LOW PRICE",IF(B3<2000,"MEDIUM PRICE","HIGH PRICE")) -> LOW PRICE
A4: Portable Mini Cordless Car Vacuum Cleaner - Blue | B4: 2199 | C4: 2923 | D4: =C4-B4 -> 724 | E4: 0.25 | F4: =IF(E4<20%,"LOW DISCOUNT",IF(E4<40%,"MEDIUM DISCOUNT","HIGH DISCOUNT")) -> MEDIUM DISCOUNT | G4: 24 | H4: 4.6 | I4: =IF(ISBLANK(H4),"NOT PROVIDED",IF(H4<3,"POOR",IF(H4<4.5,"AVERAGE","EXCELLENT"))) -> EXCELLENT | J4: =IF(B4<1000,"LOW PRICE",IF(B4<2000,"MEDIUM PRICE","HIGH PRICE")) -> HIGH PRICE
A5: Weighing Scale Digital Bathroom Body Fat Scale USB-Black | B5: 1580 | C5: 2499 | D5: =C5-B5 -> 919 | E5: 0.37 | F5: =IF(E5<20%,"LOW DISCOUNT",IF(E5<40%,"MEDIUM DISCOUNT","HIGH DISCOUNT")) -> MEDIUM DISCOUNT | G5: 7 | H5: 4.7 | I5: =IF(ISBLANK(H5),"NOT PROVIDED",IF(H5<3,"POOR",IF(H5<4.5,"AVERAGE","EXCELLENT"))) -> EXCELLENT | J5: =IF(B5<1000,"LOW PRICE",IF(B5<2000,"MEDIUM PRICE","HIGH PRICE")) -> MEDIUM PRICE
A6: Portable Home Small Air Humidifier 3-Speed Fan - Green | B6: 1740 | C6: 2356 | D6: =C6-B6 -> 616 | E6: 0.26 | F6: =IF(E6<20%,"LOW DISCOUNT",IF(E6<40%,"MEDIUM DISCOUNT","HIGH DISCOUNT")) -> MEDIUM DISCOUNT | G6: 5 | H6: 4.8 | I6: =IF(ISBLANK(H6),"NOT PROVIDED",IF(H6<3,"POOR",IF(H6<4.5,"AVERAGE","EXCELLENT"))) -> EXCELLENT | J6: =IF(B6<1000,"LOW PRICE",IF(B6<2000,"MEDIUM PRICE","HIGH PRICE")) -> MEDIUM PRICE
A7: 220V 60W Electric Soldering Iron Kits With Tools, Tips, And Multimeter | B7: 2999 | C7: 3290 | D7: =C7-B7 -> 291 | E7: 0.09 | F7: =IF(E7<20%,"LOW DISCOUNT",IF(E7<40%,"MEDIUM DISCOUNT","HIGH DISCOUNT")) -> LOW DISCOUNT | G7: 15 | H7: 4 | I7: =IF(ISBLANK(H7),"NOT PROVIDED",IF(H7<3,"POOR",IF(H7<4.5,"AVERAGE","EXCELLENT"))) -> AVERAGE | J7: =IF(B7<1000,"LOW PRICE",IF(B7<2000,"MEDIUM PRICE","HIGH PRICE")) -> HIGH PRICE
A8: 137 Pieces Cake Decorating Tool Set Baking Supplies | B8: 2319 | C8: 3032 | D8: =C8-B8 -> 713 | E8: 0.24 | F8: =IF(E8<20%,"LOW DISCOUNT",IF(E8<40%,"MEDIUM DISCOUNT","HIGH DISCOUNT")) -> MEDIUM DISCOUNT | G8: 55 | H8: 4.6 | I8: =IF(ISBLANK(H8),"NOT PROVIDED",IF(H8<3,"POOR",IF(H8<4.5,"AVERAGE","EXCELLENT"))) -> EXCELLENT | J8: =IF(B8<1000,"LOW PRICE",IF(B8<2000,"MEDIUM PRICE","HIGH PRICE")) -> HIGH PRICE
A9: Desk Foldable Fan Adjustable Fan Strong Wind 3 Gear Usb | B9: 988 | C9: 1580 | D9: =C9-B9 -> 592 | E9: 0.37 | F9: =IF(E9<20%,"LOW DISCOUNT",IF(E9<40%,"MEDIUM DISCOUNT","HIGH DISCOUNT")) -> MEDIUM DISCOUNT | G9: 2 | H9: 4 | I9: =IF(ISBLANK(H9),"NOT PROVIDED",IF(H9<3,"POOR",IF(H9<4.5,"AVERAGE","EXCELLENT"))) -> AVERAGE | J9: =IF(B9<1000,"LOW PRICE",IF(B9<2000,"MEDIUM PRICE","HIGH PRICE")) -> LOW PRICE
A10: LASA FOLDING TABLE SERVING STAND | B10: 1274 | C10: 2800 | D10: =C10-B10 -> 1526 | E10: 0.55 | F10: =IF(E10<20%,"LOW DISCOUNT",IF(E10<40%,"MEDIUM DISCOUNT","HIGH DISCOUNT")) -> HIGH DISCOUNT | G10: 5 | H10: 4.8 | I10: =IF(ISBLANK(H10),"NOT PROVIDED",IF(H10<3,"POOR",IF(H10<4.5,"AVERAGE","EXCELLENT"))) -> EXCELLENT | J10: =IF(B10<1000,"LOW PRICE",IF(B10<2000,"MEDIUM PRICE","HIGH PRICE")) -> MEDIUM PRICE
A11: 13 In 1 Home Repair Tools Box Kit Set | B11: 1600 | C11: 2929 | D11: =C11-B11 -> 1329 | E11: 0.45 | F11: =IF(E11<20%,"LOW DISCOUNT",IF(E11<40%,"MEDIUM DISCOUNT","HIGH DISCOUNT")) -> HIGH DISCOUNT | G11: 5 | H11: 3.8 | I11: =IF(ISBLANK(H11),"NOT PROVIDED",IF(H11<3,"POOR",IF(H11<4.5,"AVERAGE","EXCELLENT"))) -> AVERAGE | J11: =IF(B11<1000,"LOW PRICE",IF(B11<2000,"MEDIUM PRICE","HIGH PRICE")) -> MEDIUM PRICE
A12: Genebre 115 In 1 Screwdriver Repairing Tool Set For IPhone Cellphone Hand Tool | B12: 799 | C12: 999 | D12: =C12-B12 -> 200 | E12: 0.2 | F12: =IF(E12<20%,"LOW DISCOUNT",IF(E12<40%,"MEDIUM DISCOUNT","HIGH DISCOUNT")) -> MEDIUM DISCOUNT | G12: 12 | H12: 4.1 | I12: =IF(ISBLANK(H12),"NOT PROVIDED",IF(H12<3,"POOR",IF(H12<4.5,"AVERAGE","EXCELLENT"))) -> AVERAGE | J12: =IF(B12<1000,"LOW PRICE",IF(B12<2000,"MEDIUM PRICE","HIGH PRICE")) -> LOW PRICE
A13: 100 Pcs Crochet Hook Tool Set Knitting Hook Set With Box | B13: 990 | C13: 1500 | D13: =C13-B13 -> 510 | E13: 0.34 | F13: =IF(E13<20%,"LOW DISCOUNT",IF(E13<40%,"MEDIUM DISCOUNT","HIGH DISCOUNT")) -> MEDIUM DISCOUNT | G13: 39 | H13: 4.7 | I13: =IF(ISBLANK(H13),"NOT PROVIDED",IF(H13<3,"POOR",IF(H13<4.5,"AVERAGE","EXCELLENT"))) -> EXCELLENT | J13: =IF(B13<1000,"LOW PRICE",IF(B13<2000,"MEDIUM PRICE","HIGH PRICE")) -> LOW PRICE
... A22: 3PCS Single Head Knitting Crochet Sweater Needle Set | B22: 38 | C22: 80 | D22: =C22-B22 -> 42 | E22: 0.53 | F22: =IF(E22<20%,"LOW DISCOUNT",IF(E22<40%,"MEDIUM DISCOUNT","HIGH DISCOUNT")) -> HIGH DISCOUNT | G22: 13 | H22: 3.3 | I22: =IF(ISBLANK(H22),"NOT PROVIDED",IF(H22<3,"POOR",IF(H22<4.5,"AVERAGE","EXCELLENT"))) -> AVERAGE | J22: =IF(B22<1000,"LOW PRICE",IF(B22<2000,"MEDIUM PRICE","HIGH PRICE")) -> LOW PRICE
A23: 4pcs Bathroom/Kitchen Towel Rack,Roll Paper Holder,Towel Bars,Hook | B23: 1860 | C23: 3220 | D23: =C23-B23 -> 1360 | E23: 0.42 | F23: =IF(E23<20%,"LOW DISCOUNT",IF(E23<40%,"MEDIUM DISCOUNT","HIGH DISCOUNT")) -> HIGH DISCOUNT | I23: =IF(ISBLANK(H23),"NOT PROVIDED",IF(H23<3,"POOR",IF(H23<4.5,"AVERAGE","EXCELLENT"))) -> NOT PROVIDED | J23: =IF(B23<1000,"LOW PRICE",IF(B23<2000,"MEDIUM PRICE","HIGH PRICE")) -> MEDIUM PRICE
